Defaulting to user installation because normal site-packages is not writeable
Requirement already satisfied: openai in /home/at4932/.local/lib/python3.8/site-packages (0.27.2)
Requirement already satisfied: requests>=2.20 in /share/apps/anaconda3/2020.07/lib/python3.8/site-packages (from openai) (2.24.0)
Requirement already satisfied: tqdm in /home/at4932/.local/lib/python3.8/site-packages (from openai) (4.64.1)
Requirement already satisfied: aiohttp in /home/at4932/.local/lib/python3.8/site-packages (from openai) (3.8.4)
Requirement already satisfied: urllib3!=1.25.0,!=1.25.1,<1.26,>=1.21.1 in /share/apps/anaconda3/2020.07/lib/python3.8/site-packages (from requests>=2.20->openai) (1.25.9)
Requirement already satisfied: certifi>=2017.4.17 in /share/apps/anaconda3/2020.07/lib/python3.8/site-packages (from requests>=2.20->openai) (2020.6.20)
Requirement already satisfied: chardet<4,>=3.0.2 in /share/apps/anaconda3/2020.07/lib/python3.8/site-packages (from requests>=2.20->openai) (3.0.4)
Requirement already satisfied: idna<3,>=2.5 in /share/apps/anaconda3/2020.07/lib/python3.8/site-packages (from requests>=2.20->openai) (2.10)
Requirement already satisfied: multidict<7.0,>=4.5 in /home/at4932/.local/lib/python3.8/site-packages (from aiohttp->openai) (6.0.4)
Requirement already satisfied: aiosignal>=1.1.2 in /home/at4932/.local/lib/python3.8/site-packages (from aiohttp->openai) (1.3.1)
Requirement already satisfied: yarl<2.0,>=1.0 in /home/at4932/.local/lib/python3.8/site-packages (from aiohttp->openai) (1.8.2)
Requirement already satisfied: async-timeout<5.0,>=4.0.0a3 in /home/at4932/.local/lib/python3.8/site-packages (from aiohttp->openai) (4.0.2)
Requirement already satisfied: charset-normalizer<4.0,>=2.0 in /home/at4932/.local/lib/python3.8/site-packages (from aiohttp->openai) (3.1.0)
Requirement already satisfied: frozenlist>=1.1.1 in /home/at4932/.local/lib/python3.8/site-packages (from aiohttp->openai) (1.3.3)
Requirement already satisfied: attrs>=17.3.0 in /share/apps/anaconda3/2020.07/lib/python3.8/site-packages (from aiohttp->openai) (19.3.0)
Defaulting to user installation because normal site-packages is not writeable
Requirement already satisfied: python-dotenv in /home/at4932/.local/lib/python3.8/site-packages (1.0.0)
Traceback (most recent call last):
  File "/share/apps/anaconda3/2020.07/lib/python3.8/site-packages/pandas/core/indexes/base.py", line 2646, in get_loc
    return self._engine.get_loc(key)
  File "pandas/_libs/index.pyx", line 111, in pandas._libs.index.IndexEngine.get_loc
  File "pandas/_libs/index.pyx", line 138, in pandas._libs.index.IndexEngine.get_loc
  File "pandas/_libs/hashtable_class_helper.pxi", line 1619, in pandas._libs.hashtable.PyObjectHashTable.get_item
  File "pandas/_libs/hashtable_class_helper.pxi", line 1627, in pandas._libs.hashtable.PyObjectHashTable.get_item
KeyError: 'Scientific Names'

During handling of the above exception, another exception occurred:

Traceback (most recent call last):
  File "annotation_script.py", line 27, in <module>
    sciNames = df["Scientific Names"].tolist()
  File "/share/apps/anaconda3/2020.07/lib/python3.8/site-packages/pandas/core/frame.py", line 2800, in __getitem__
    indexer = self.columns.get_loc(key)
  File "/share/apps/anaconda3/2020.07/lib/python3.8/site-packages/pandas/core/indexes/base.py", line 2648, in get_loc
    return self._engine.get_loc(self._maybe_cast_indexer(key))
  File "pandas/_libs/index.pyx", line 111, in pandas._libs.index.IndexEngine.get_loc
  File "pandas/_libs/index.pyx", line 138, in pandas._libs.index.IndexEngine.get_loc
  File "pandas/_libs/hashtable_class_helper.pxi", line 1619, in pandas._libs.hashtable.PyObjectHashTable.get_item
  File "pandas/_libs/hashtable_class_helper.pxi", line 1627, in pandas._libs.hashtable.PyObjectHashTable.get_item
KeyError: 'Scientific Names'

real	0m1.621s
user	0m0.527s
sys	0m0.128s
